#VRML_SIM R2022a utf8
WorldInfo {
}
Viewpoint {
  orientation -0.5773502691896258 0.5773502691896258 0.5773502691896258 2.0944
  position 0.001217846839649893 1.144343701435833e-05 3.358612437409094
}
TexturedBackground {
}
TexturedBackgroundLight {
}
RectangleArena {
  floorSize 2 2
  wallHeight 0.2
}
DEF superRobot Robot {
  translation 0.75 -0.75 0.001
  rotation 0 0 1 3.14
  children [
    Solid {
      translation -0.045 0 0.006
      children [
        DEF shape Shape {
          appearance PBRAppearance {
            roughness 1
            metalness 0
          }
          geometry Cylinder {
            height 0.01
            radius 0.01
          }
        }
      ]
      name "solid(5)"
      boundingObject USE shape
      physics Physics {
      }
    }
    Solid {
      translation 0.045 0 0.006
      children [
        Shape {
          appearance PBRAppearance {
            roughness 1
            metalness 0
          }
          geometry Cylinder {
            height 0.01
            radius 0.01
          }
        }
      ]
      name "solid(4)"
      boundingObject USE shape
      physics Physics {
      }
    }
    Pen {
      translation 0 0 -0.002
      inkColor 0 1 0
      leadSize 0.2
    }
    Lidar {
      translation 0 0 0.083
      rotation 0 0 1 3.14
      fieldOfView 6.283
      numberOfLayers 1
    }
    DEF Body Transform {
      translation 0 0 0.0415
      children [
        Shape {
          appearance PBRAppearance {
            baseColor 1 0 0
            roughness 1
            metalness 0
          }
          geometry Cylinder {
            height 0.08
            radius 0.045
          }
        }
      ]
    }
    HingeJoint {
      jointParameters HingeJointParameters {
        axis 0 1 0
        anchor 0 0.045 0.025
      }
      device [
        RotationalMotor {
          name "motor_1"
        }
        DEF ps_1 PositionSensor {
          name "ps_1"
        }
      ]
      endPoint Solid {
        translation 0 0.045 0.025
        rotation 1 -1.720747563216668e-09 1.7193768480007156e-09 1.5699999999999963
        children [
          DEF wheel Shape {
            appearance PBRAppearance {
              baseColor 1 0 0
              roughness 1
              metalness 0
            }
            geometry Cylinder {
              height 0.01
              radius 0.025
            }
          }
        ]
        boundingObject USE wheel
        physics DEF Wheel_physics Physics {
        }
      }
    }
    HingeJoint {
      jointParameters HingeJointParameters {
        axis 0 1 0
        anchor 0 -0.045 0.025
      }
      device [
        RotationalMotor {
          name "motor_2"
        }
        DEF ps_2 PositionSensor {
          name "ps_2"
        }
      ]
      endPoint Solid {
        translation 0 -0.045 0.025
        rotation 1 -5.517237986952128e-09 5.512846473825698e-09 1.5699999999999752
        children [
          USE wheel
        ]
        name "solid(1)"
        boundingObject USE wheel
        physics USE Wheel_physics
      }
    }
    Solid {
      translation 0.045 0.015 0.07
      children [
        DEF Eye Shape {
          appearance PBRAppearance {
            baseColor 1 0 0
            roughness 1
            metalness 0
          }
          geometry Box {
            size 0.005 0.005 0.005
          }
        }
      ]
      name "solid(2)"
    }
    Solid {
      translation 0.045 -0.015 0.07
      children [
        USE Eye
      ]
      name "solid(3)"
    }
  ]
  name "robot(1)"
  boundingObject USE Body
  physics Physics {
  }
  controller "Lidar_Mapping"
  supervisor TRUE
}
DEF Hedef Solid {
  translation -0.75 -0.75 0.01
  children [
    DEF shape Shape {
      appearance PBRAppearance {
        baseColor 0 1 0
        roughness 1
        metalness 0
      }
      geometry Cylinder {
        height 0.01
        radius 0.05
      }
    }
  ]
}
Wall {
  translation 0.5 -0.5 0
  rotation 0 0 1 1.57
  size 0.01 1 0.2
}
Wall {
  translation -0.5 -0.25 0
  name "wall(1)"
  size 0.01 0.5 0.2
}
Wall {
  rotation 0 0 1 1.57
  name "wall(2)"
  size 0.01 1 0.2
}
Wall {
  translation 0.5 0.5 0
  name "wall(3)"
  size 0.01 1 0.2
}
Wall {
  translation -0.5 0.5 0
  rotation 0 0 1 1.57
  name "wall(4)"
  size 0.01 1 0.2
}
